<?xml version="1.0"?>
<robot xmlns:xacro="http://ros.org/wiki/xacro">
    <xacro:macro name="caster_holder" params="side yshift">
        <link name="${side}_ch_link">
            <visual>
                <origin xyz="0 0 0" rpy="${pi/2} 0 0" />
                <geometry>
                    <cylinder radius="0.10" length="0.04" />
                </geometry>
                <material name="Gray">
                    <color rgba="0.5 0.5 0.5 1.0" />
                </material>
            </visual>

            <collision>
                <origin xyz="0 0 0" rpy="${pi/2} 0 0" />
                <geometry>
                    <cylinder radius="0.10" length="0.04" />
                </geometry>
            </collision>

            <xacro:cylinder_inertia m="0.5" r="0.10" h="0.04" />
        </link>

        <joint name="${side}_ch_joint" type="continuous">
            <parent link="base_link" />
            <child link="${side}_link" />
            <origin xyz="${x_reflect*wheel_xoff} ${y_reflect*(base_width/2+wheel_ygap)} ${-wheel_zoff}" rpy="0 0 0" />
            <axis xyz="0 1 0" />
        </joint>
    </xacro:macro>

    <link name="caster_rod_left">
        <visual>
            <origin xyz="0 0 0" rpy="0 0 0" />
            <geometry>
                <box size="0.02 0.02 0.1" />
            </geometry>
            <material name="Cyan">
                <color rgba="0 1.0 1.0 1.0" />
            </material>
        </visual>

        <xacro:sphere_inertia m="0.5" r="${(wheel_radius+wheel_zoff-(base_height/2))}" />
    </link>

    <link name="front_caster">
      <visual>
        <geometry>
          <sphere radius="${(wheel_radius+wheel_zoff-(base_height/2))}"/>
        </geometry>
        <material name="Cyan">
          <color rgba="0 1.0 1.0 1.0"/>
        </material>
      </visual>

      <collision>
        <origin xyz="0 0 0" rpy="0 0 0"/>
        <geometry>
          <sphere radius="${(wheel_radius+wheel_zoff-(base_height/2))}"/>
        </geometry>
      </collision>

      <xacro:sphere_inertia m="0.5" r="${(wheel_radius+wheel_zoff-(base_height/2))}"/>
    </link>

    <joint name="caster_joint" type="continuous">
        <parent link="caster_rod_left" />
        <child link="front_caster" />
        <origin xyz="0.0 0.0 ${-(base_height/2)}" rpy="0 0 0" />
        <axis xyz="0.0 1.0 0.0" />
    </joint>

    <joint name="caster_rod_joint" type="continuous">
        <parent link="base_link" />
        <child link="caster_rod_left" />
        <origin xyz="0.14 0.0 0.0" rpy="0 0 0" />
        <axis xyz="0.0 0.0 1.0" />
        <!-- <limit lower="-0.5" upper="0.5" effort="30" velocity="1.0"/> -->
    </joint>
</robot>
